0it [00:00, ?it/s]
Traceback (most recent call last):
  File "/sw/centos/anaconda3/5.0.1/lib/python3.6/site-packages/pandas/core/indexes/base.py", line 2483, in get_value
    return libts.get_value_box(s, key)
  File "pandas/_libs/tslib.pyx", line 923, in pandas._libs.tslib.get_value_box (pandas/_libs/tslib.c:18843)
  File "pandas/_libs/tslib.pyx", line 932, in pandas._libs.tslib.get_value_box (pandas/_libs/tslib.c:18477)
TypeError: 'str' object cannot be interpreted as an integer

During handling of the above exception, another exception occurred:

Traceback (most recent call last):
  File "/u/as3ek/github/reversible-meme/scripts/meme_crawler.py", line 56, in <module>
    img_name = row['title']
  File "/sw/centos/anaconda3/5.0.1/lib/python3.6/site-packages/pandas/core/series.py", line 601, in __getitem__
    result = self.index.get_value(self, key)
  File "/sw/centos/anaconda3/5.0.1/lib/python3.6/site-packages/pandas/core/indexes/base.py", line 2491, in get_value
    raise e1
  File "/sw/centos/anaconda3/5.0.1/lib/python3.6/site-packages/pandas/core/indexes/base.py", line 2477, in get_value
    tz=getattr(series.dtype, 'tz', None))
  File "pandas/_libs/index.pyx", line 98, in pandas._libs.index.IndexEngine.get_value
  File "pandas/_libs/index.pyx", line 106, in pandas._libs.index.IndexEngine.get_value
  File "pandas/_libs/index.pyx", line 154, in pandas._libs.index.IndexEngine.get_loc
  File "pandas/_libs/hashtable_class_helper.pxi", line 1210, in pandas._libs.hashtable.PyObjectHashTable.get_item
  File "pandas/_libs/hashtable_class_helper.pxi", line 1218, in pandas._libs.hashtable.PyObjectHashTable.get_item
KeyError: 'title'
